[2022-07-11 06:43:20,343]-werkzeug-INFO- * Running on http://127.0.0.1:5000 (Press CTRL+C to quit)
[2022-07-11 06:43:26,029]-app-ERROR-Exception on / [GET]
Traceback (most recent call last):
  File "app.py", line 12, in index
    logging.info(f"this is currently testing app")
AttributeError: module 'InsurancePremiumPrediction.logger.logging' has no attribute 'info'

The above exception was the direct cause of the following exception:

Traceback (most recent call last):
  File "B:\Python_projects\Insurance_Prediction\venv\lib\site-packages\flask\app.py", line 2077, in wsgi_app
    response = self.full_dispatch_request()
  File "B:\Python_projects\Insurance_Prediction\venv\lib\site-packages\flask\app.py", line 1525, in full_dispatch_request
    rv = self.handle_user_exception(e)
  File "B:\Python_projects\Insurance_Prediction\venv\lib\site-packages\flask\app.py", line 1523, in full_dispatch_request
    rv = self.dispatch_request()
  File "B:\Python_projects\Insurance_Prediction\venv\lib\site-packages\flask\app.py", line 1509, in dispatch_request
    return self.ensure_sync(self.view_functions[rule.endpoint])(**req.view_args)
  File "app.py", line 15, in index
    raise InsuranceException(e,sys) from e
InsurancePremiumPrediction.Exception.InsuranceException: Error occured in script:
        [app.py] at try block line number :
        [12] and exception block number [15],
        error_message :[module 'InsurancePremiumPrediction.logger.logging' has no attribute 'info']
[2022-07-11 06:43:26,037]-werkzeug-INFO-127.0.0.1 - - [11/Jul/2022 06:43:26] "[35m[1mGET / HTTP/1.1[0m" 500 -
[2022-07-11 06:43:29,057]-app-ERROR-Exception on / [GET]
Traceback (most recent call last):
  File "app.py", line 12, in index
    logging.info(f"this is currently testing app")
AttributeError: module 'InsurancePremiumPrediction.logger.logging' has no attribute 'info'

The above exception was the direct cause of the following exception:

Traceback (most recent call last):
  File "B:\Python_projects\Insurance_Prediction\venv\lib\site-packages\flask\app.py", line 2077, in wsgi_app
    response = self.full_dispatch_request()
  File "B:\Python_projects\Insurance_Prediction\venv\lib\site-packages\flask\app.py", line 1525, in full_dispatch_request
    rv = self.handle_user_exception(e)
  File "B:\Python_projects\Insurance_Prediction\venv\lib\site-packages\flask\app.py", line 1523, in full_dispatch_request
    rv = self.dispatch_request()
  File "B:\Python_projects\Insurance_Prediction\venv\lib\site-packages\flask\app.py", line 1509, in dispatch_request
    return self.ensure_sync(self.view_functions[rule.endpoint])(**req.view_args)
  File "app.py", line 15, in index
    raise InsuranceException(e,sys) from e
InsurancePremiumPrediction.Exception.InsuranceException: Error occured in script:
        [app.py] at try block line number :
        [12] and exception block number [15],
        error_message :[module 'InsurancePremiumPrediction.logger.logging' has no attribute 'info']
[2022-07-11 06:43:29,057]-werkzeug-INFO-127.0.0.1 - - [11/Jul/2022 06:43:29] "[35m[1mGET / HTTP/1.1[0m" 500 -
[2022-07-11 06:43:50,036]-app-ERROR-Exception on / [GET]
Traceback (most recent call last):
  File "app.py", line 12, in index
    logging.info(f"this is currently testing app")
AttributeError: module 'InsurancePremiumPrediction.logger.logging' has no attribute 'info'

The above exception was the direct cause of the following exception:

Traceback (most recent call last):
  File "B:\Python_projects\Insurance_Prediction\venv\lib\site-packages\flask\app.py", line 2077, in wsgi_app
    response = self.full_dispatch_request()
  File "B:\Python_projects\Insurance_Prediction\venv\lib\site-packages\flask\app.py", line 1525, in full_dispatch_request
    rv = self.handle_user_exception(e)
  File "B:\Python_projects\Insurance_Prediction\venv\lib\site-packages\flask\app.py", line 1523, in full_dispatch_request
    rv = self.dispatch_request()
  File "B:\Python_projects\Insurance_Prediction\venv\lib\site-packages\flask\app.py", line 1509, in dispatch_request
    return self.ensure_sync(self.view_functions[rule.endpoint])(**req.view_args)
  File "app.py", line 15, in index
    raise InsuranceException(e,sys) from e
InsurancePremiumPrediction.Exception.InsuranceException: Error occured in script:
        [app.py] at try block line number :
        [12] and exception block number [15],
        error_message :[module 'InsurancePremiumPrediction.logger.logging' has no attribute 'info']
[2022-07-11 06:43:50,036]-werkzeug-INFO-127.0.0.1 - - [11/Jul/2022 06:43:50] "[35m[1mGET / HTTP/1.1[0m" 500 -
